<?xml version="1.0" ?><robot name="sysID_SM40BL">
  
  <link name="mount_sm40bl">
    <inertial>
      <origin xyz="0.061853 0.0904812 0.072305" rpy="0 0 0"/>
      <mass value="0.113746"/>
      <inertia ixx="8.41104e-05" ixy="-1.98862e-05" ixz="-6.81899e-08" iyy="4.31852e-05" iyz="-3.30358e-08" izz="0.000109658"/>
    </inertial>
    
    <visual>
      <origin xyz="0.061853 0.0904812 0.072305" rpy="0 -0 0"/>
      <geometry>
        <mesh filename="package:///meshes/mount_sm40bl_visual.stl"/>
      </geometry>
      <material name="mount_sm40bl_parts_material">
        <color rgba="0.597754 0.750234 0.577238 1.0"/>
      </material>
    </visual>
    <collision>
      <origin xyz="0.061853 0.0904812 0.072305" rpy="0 -0 0"/>
      <geometry>
        <mesh filename="package:///meshes/mount_sm40bl_collision.stl"/>
      </geometry>
    </collision>
  </link>
  
  <link name="sm40bl_mu_20190118">
    <inertial>
      <origin xyz="0.0679425 2.90485e-11 0.0209492" rpy="0 0 0"/>
      <mass value="0.236902"/>
      <inertia ixx="0.000343673" ixy="3.29797e-14" ixz="-1.40372e-08" iyy="0.000499905" iyz="1.88524e-12" izz="0.000298438"/>
    </inertial>
    
    <visual>
      <origin xyz="0.0679425 2.90485e-11 0.0209492" rpy="1.5708 -5.25809e-17 -3.14159"/>
      <geometry>
        <mesh filename="package:///meshes/sm40bl_mu_20190118_visual.stl"/>
      </geometry>
      <material name="sm40bl_mu_20190118_parts_material">
        <color rgba="0.64664 0.655575 0.662099 1.0"/>
      </material>
    </visual>
    <collision>
      <origin xyz="0.0679425 2.90485e-11 0.0209492" rpy="1.5708 -5.25809e-17 -3.14159"/>
      <geometry>
        <mesh filename="package:///meshes/sm40bl_mu_20190118_collision.stl"/>
      </geometry>
    </collision>
  </link>
  
  <joint name="joint_0" type="revolute">
    <origin xyz="0.0470055 0.0647694 0.0722778" rpy="1.5708 -0 3.14159"/>
    <parent link="mount_sm40bl"/>
    <child link="sm40bl_mu_20190118"/>
    <axis xyz="0 0 1"/>
    <limit effort="10" velocity="10" lower="-1.5708" upper="1.5708"/>
  </joint>
</robot>